Workbook

Sheet Assumptions
A1: THE VALLEY CLEAN TEAM — PRICING ASSUMPTIONS
A2: Reconciled to BookingKoala 2026-08-21 — BK is authoritative
A3: CLIENT-FACING BILLING RATES
A4: Input | B4: Value | C4: Notes
A5: Standard hourly billing rate | B5: 62.5 | C5: Rate per cleaner-hour quoted to clients
A6: Post-construction hourly rate | B6: 95 | C6: Higher rate for specialty post-construction work
A8: SUBCONTRACTOR MODEL
A9: Input | B9: Value | C9: Notes
A10: Sub rate — low end | B10: 0.4 | C10: Lowest percentage you pay a sub
A11: Sub rate — high end | B11: 0.5 | C11: Highest percentage you pay a sub
A12: Sub rate for margin calculations | B12: 0.45 | C12: Midpoint — adjust to your most common rate
A13: Target gross margin | B13: 0.38 | C13: (Revenue − All Costs) ÷ Revenue
A15: TRAVEL FEES BY ZONE · Flat per-job fee paid to sub for gas
A16: Input | B16: Value | C16: Notes
A17: Zone 1 — Nashville core (closest) | B17: 5 | C17: Local jobs
A18: Zone 2 | B18: 8
A19: Zone 3 — Mid-range | B19: 10
A20: Zone 4 | B20: 12
A21: Zone 5 — Furthest out | B21: 15 | C21: Furthest service area
A22: Zone used for margin calculations | B22: =B19 | C22: Defaults to Zone 3 — change formula to B17–B21 for different zone
A24: TODD'S FIXED COSTS PER JOB · Costs NOT covered by the sub
A25: Input | B25: Value | C25: Notes
A26: Software & tech (GHL, scheduling, etc.) | B26: 45 | C26: Monthly cost ÷ avg jobs per month — update this number
A27: Marketing & sales allocation | B27: 25 | C27: Monthly ad/lead spend ÷ avg jobs per month
A28: Total fixed cost per job | B28: =B26+B27 | C28: Auto-calculated — do not edit
A30: TIME ESTIMATES · Hours per 1,000 sq ft — used for scheduling
A31: Service | B31: Hrs / 1,000 sq ft | C31: Example
A32: Deep clean / first visit | B32: 2.625 | C32: ~21 hrs for an 8,000 sq ft home
A33: Standard / recurring clean | B33: 1.875 | C33: ~15 hrs for an 8,000 sq ft home
A34: Move in / out | B34: 2.625 | C34: Same scope as deep clean
A35: Post-construction final clean | B35: 3.125 | C35: ~25 hrs for an 8,000 sq ft new build
A37: RECURRING DISCOUNTS · Applied to Standard Clean price
A38: Input | B38: Value | C38: Notes
A39: Monthly | B39: 0.15 | C39: 15% off standard
A40: Bi-weekly | B40: 0.25 | C40: 25% off standard
A41: Weekly | B41: 0.3 | C41: 30% off standard
A43: MINIMUM PRICES
A44: Deep clean minimum | B44: 200
A45: Standard clean minimum | B45: 200
A46: Weekly recurring minimum | B46: 150
...

Sheet Pricing Table
A1: THE VALLEY CLEAN TEAM — PRICING TABLE
A2: Orange (cols B–S, 750–6,500 sq ft) = existing pricing. Blue (cols T–Z, 7,000–10,000 sq ft) = extended, market-rate grounded. Amber rows = estimated labor hours for scheduling. Discounts: Monthly −15% | Bi-Weekly −25% | Weekly −30% off Standard.
A3: DEEP CLEAN (First Cleaning)
A4: Sq Ft → | B4: 750 | C4: 1000 | D4: 1250 | E4: 1500 | F4: 1800 | G4: 2100 | H4: 2400 | I4: 2700 | J4: 3000 | K4: 3300 | L4: 3600 | M4: 4000 | N4: 4400 | O4: 4800 | P4: 5200 | Q4: 5600 | R4: 6000 | S4: 6499 | T4: 6999 | U4: 7499 | V4: 7999 | W4: 8499 | X4: 8999 | Y4: 9499 | Z4: 9999 | AA4: 10000
A5: First Cleaning (Deep Clean) | B5: 276 | C5: 311 | D5: 346 | E5: 381 | F5: 416 | G5: 451 | H5: 506 | I5: 561 | J5: 616 | K5: 671 | L5: 726 | M5: 781 | N5: 836 | O5: 891 | P5: 946 | Q5: 1001 | R5: 1056 | S5: 1056 | T5: 1170 | U5: 1350 | V5: 1550 | W5: 1750 | X5: 1950 | Y5: 2150 | Z5: 2350 | AA5: 2550
A6: Per Sq Ft | B6: =IF(B4>0,B5/B4,"") | C6: =IF(C4>0,C5/C4,"") | D6: =IF(D4>0,D5/D4,"") | E6: =IF(E4>0,E5/E4,"") | F6: =IF(F4>0,F5/F4,"") | G6: =IF(G4>0,G5/G4,"") | H6: =IF(H4>0,H5/H4,"") | I6: =IF(I4>0,I5/I4,"") | ... AA6: =IF(AA4>0,AA5/AA4,"")
A7: Est. Labor Hours | B7: =ROUND(B4/1000*Assumptions!$B$32,1) | C7: =ROUND(C4/1000*Assumptions!$B$32,1) | D7: =ROUND(D4/1000*Assumptions!$B$32,1) | E7: =ROUND(E4/1000*Assumptions!$B$32,1) | F7: =ROUND(F4/1000*Assumptions!$B$32,1) | G7: =ROUND(G4/1000*Assumptions!$B$32,1) | H7: =ROUND(H4/1000*Assumptions!$B$32,1) | I7: =ROUND(I4/1000*Assumptions!$B$32,1) | ... AA7: =ROUND(AA4/1000*Assumptions!$B$32,1)
A9: STANDARD / RECURRING CLEAN
A10: Sq Ft → | B10: 750 | C10: 1000 | D10: 1250 | E10: 1500 | F10: 1800 | G10: 2100 | H10: 2400 | I10: 2700 | J10: 3000 | K10: 3300 | L10: 3600 | M10: 4000 | N10: 4400 | O10: 4800 | P10: 5200 | Q10: 5600 | R10: 6000 | S10: 6499 | T10: 6999 | U10: 7499 | V10: 7999 | W10: 8499 | X10: 8999 | Y10: 9499 | Z10: 9999 | AA10: 10000
A11: Standard Clean (one-time) | B11: 176 | C11: 211 | D11: 246 | E11: 281 | F11: 316 | G11: 351 | H11: 381 | I11: 436 | J11: 491 | K11: 546 | L11: 601 | M11: 656 | N11: 711 | O11: 766 | P11: 821 | Q11: 876 | R11: 931 | S11: 931 | T11: 1045 | U11: 1200 | V11: 1375 | W11: 1550 | X11: 1725 | Y11: 1900 | Z11: 2075 | AA11: 2250
A12: Monthly Clean (15% off) | B12: 149 | C12: 179 | D12: 209 | E12: 239 | F12: 268 | G12: 298 | H12: 324 | I12: 370 | J12: 417 | K12: 464 | L12: 511 | M12: 557 | N12: 604 | O12: 651 | P12: 698 | Q12: 744 | R12: 791 | S12: 791 | T12: 888 | U12: 1020 | V12: 1170 | W12: 1320 | X12: 1470 | Y12: 1615 | Z12: 1760 | AA12: 1910
A13: Bi-Weekly Clean (25% off) | B13: 132 | C13: 158 | D13: 184 | E13: 211 | F13: 237 | G13: 263 | H13: 286 | I13: 327 | J13: 368 | K13: 409 | L13: 451 | M13: 492 | N13: 533 | O13: 574 | P13: 616 | Q13: 657 | R13: 698 | S13: 698 | T13: 784 | U13: 900 | V13: 1030 | W13: 1160 | X13: 1290 | Y13: 1425 | Z13: 1560 | AA13: 1690
A14: Weekly Clean (30% off) | B14: 123 | C14: 147 | D14: 172 | E14: 196 | F14: 221 | G14: 245 | H14: 266 | I14: 305 | J14: 343 | K14: 382 | L14: 420 | M14: 459 | N14: 497 | O14: 536 | P14: 574 | Q14: 613 | R14: 651 | S14: 651 | T14: 732 | U14: 840 | V14: 960 | W14: 1090 | X14: 1210 | Y14: 1330 | Z14: 1450 | AA14: 1580
A15: Weekly — Per Sq Ft | B15: =IF(B10>0,B14/B10,"") | C15: =IF(C10>0,C14/C10,"") | D15: =IF(D10>0,D14/D10,"") | E15: =IF(E10>0,E14/E10,"") | F15: =IF(F10>0,F14/F10,"") | G15: =IF(G10>0,G14/G10,"") | H15: =IF(H10>0,H14/H10,"") | I15: =IF(I10>0,I14/I10,"") | ... AA15: =IF(AA10>0,AA14/AA10,"")
A16: Est. Labor Hours | B16: =ROUND(B10/1000*Assumptions!$B$33,1) | C16: =ROUND(C10/1000*Assumptions!$B$33,1) | D16: =ROUND(D10/1000*Assumptions!$B$33,1) | E16: =ROUND(E10/1000*Assumptions!$B$33,1) | F16: =ROUND(F10/1000*Assumptions!$B$33,1) | G16: =ROUND(G10/1000*Assumptions!$B$33,1) | H16: =ROUND(H10/1000*Assumptions!$B$33,1) | I16: =ROUND(I10/1000*Assumptions!$B$33,1) | ... AA16: =ROUND(AA10/1000*Assumptions!$B$33,1)
A18: MOVE IN / MOVE OUT (+$75 above Deep Clean)
A19: Sq Ft → | B19: 750 | C19: 1000 | D19: 1250 | E19: 1500 | F19: 1800 | G19: 2100 | H19: 2400 | I19: 2700 | J19: 3000 | K19: 3300 | L19: 3600 | M19: 4000 | N19: 4400 | O19: 4800 | P19: 5200 | Q19: 5600 | R19: 6000 | S19: 6499 | T19: 6999 | U19: 7499 | V19: 7999 | W19: 8499 | X19: 8999 | Y19: 9499 | Z19: 9999 | AA19: 10000
A20: Move In / Out Clean | B20: 351 | C20: 386 | D20: 421 | E20: 456 | F20: 491 | G20: 526 | H20: 581 | I20: 636 | J20: 691 | K20: 746 | L20: 801 | M20: 856 | N20: 911 | O20: 966 | P20: 1021 | Q20: 1076 | R20: 1131 | S20: 1131 | T20: 1181 | U20: 1425 | V20: 1625 | W20: 1825 | X20: 2025 | Y20: 2225 | Z20: 2425 | AA20: 2625
A21: Per Sq Ft | B21: =IF(B19>0,B20/B19,"") | C21: =IF(C19>0,C20/C19,"") | D21: =IF(D19>0,D20/D19,"") | E21: =IF(E19>0,E20/E19,"") | F21: =IF(F19>0,F20/F19,"") | G21: =IF(G19>0,G20/G19,"") | H21: =IF(H19>0,H20/H19,"") | I21: =IF(I19>0,I20/I19,"") | ... AA21: =IF(AA19>0,AA20/AA19,"")
A22: Est. Labor Hours | B22: =ROUND(B19/1000*Assumptions!$B$34,1) | C22: =ROUND(C19/1000*Assumptions!$B$34,1) | D22: =ROUND(D19/1000*Assumptions!$B$34,1) | E22: =ROUND(E19/1000*Assumptions!$B$34,1) | F22: =ROUND(F19/1000*Assumptions!$B$34,1) | G22: =ROUND(G19/1000*Assumptions!$B$34,1) | H22: =ROUND(H19/1000*Assumptions!$B$34,1) | I22: =ROUND(I19/1000*Assumptions!$B$34,1) | ... AA22: =ROUND(AA19/1000*Assumptions!$B$34,1)
A24: POST-CONSTRUCTION CLEAN UP
A25: ⚠️ RATE CHANGE FOR 7,000+ SQ FT: Existing prices used '50% above Move In/Out' formula — which underprices large new builds. Extended range uses $0.50/sq ft, grounded in Nashville post-construction market rates ($3,200–$4,400 for 8,000 sq ft).
A26: Sq Ft → | B26: 750 | C26: 1000 | D26: 1250 | E26: 1500 | F26: 1800 | G26: 2100 | H26: 2400 | I26: 2700 | J26: 3000 | K26: 3300 | L26: 3600 | M26: 4000 | N26: 4400 | O26: 4700 | P26: 5200 | Q26: 5600 | R26: 6000 | S26: 6500 | T26: 7000 | U26: 7500 | V26: 8000 | W26: 8500 | X26: 9000 | Y26: 9500 | Z26: 10000
A27: Construction Clean Up | B27: 526 | C27: 579 | D27: 631 | E27: 684 | F27: 736 | G27: 789 | H27: 871 | I27: 954 | J27: 1036 | K27: 1119 | L27: 1201 | M27: 1284 | N27: 1366 | O27: 1449 | P27: 1531 | Q27: 1614 | R27: 1696 | S27: 1820 | T27: 3500 | U27: 3750 | V27: 4000 | W27: 4250 | X27: 4500 | Y27: 4750 | Z27: 5000
A28: Per Sq Ft | B28: =IF(B26>0,B27/B26,"") | C28: =IF(C26>0,C27/C26,"") | D28: =IF(D26>0,D27/D26,"") | E28: =IF(E26>0,E27/E26,"") | F28: =IF(F26>0,F27/F26,"") | G28: =IF(G26>0,G27/G26,"") | H28: =IF(H26>0,H27/H26,"") | I28: =IF(I26>0,I27/I26,"") | ... Z28: =IF(Z26>0,Z27/Z26,"")
A29: Est. Labor Hours | B29: =ROUND(B26/1000*Assumptions!$B$35,1) | C29: =ROUND(C26/1000*Assumptions!$B$35,1) | D29: =ROUND(D26/1000*Assumptions!$B$35,1) | E29: =ROUND(E26/1000*Assumptions!$B$35,1) | F29: =ROUND(F26/1000*Assumptions!$B$35,1) | G29: =ROUND(G26/1000*Assumptions!$B$35,1) | H29: =ROUND(H26/1000*Assumptions!$B$35,1) | I29: =ROUND(I26/1000*Assumptions!$B$35,1) | ... Z29: =ROUND(Z26/1000*Assumptions!$B$35,1)
A31: SUBCONTRACTOR FLOOR CHECK — Minimum Viable Job Price by Zone & Sub Rate
A32: Formula: (Travel Fee + Fixed Costs Per Job) ÷ (1 − Sub Rate % − Target Margin %) Any job priced above the floor for its zone/sub rate hits your margin target.
A33: Zone / Travel Fee | B33: 40% Sub Rate | C33: 45% Sub Rate | D33: 50% Sub Rate
A34: Zone 1 — $5 travel | B34: =(Assumptions!$B$17+Assumptions!$B$28)/(1-Assumptions!$B$10-Assumptions!$B$13) | C34: =(Assumptions!$B$17+Assumptions!$B$28)/(1-Assumptions!$B$12-Assumptions!$B$13) | D34: =(Assumptions!$B$17+Assumptions!$B$28)/(1-Assumptions!$B$11-Assumptions!$B$13) | E34: ← Any job priced above the number in its row hits your margin target. Larger jobs generate higher margins because fixed costs become a smaller % of revenue. See Margin table below.
A35: Zone 2 — $8 travel | B35: =(Assumptions!$B$18+Assumptions!$B$28)/(1-Assumptions!$B$10-Assumptions!$B$13) | C35: =(Assumptions!$B$18+Assumptions!$B$28)/(1-Assumptions!$B$12-Assumptions!$B$13) | D35: =(Assumptions!$B$18+Assumptions!$B$28)/(1-Assumptions!$B$11-Assumptions!$B$13)
A36: Zone 3 — $10 travel | B36: =(Assumptions!$B$19+Assumptions!$B$28)/(1-Assumptions!$B$10-Assumptions!$B$13) | C36: =(Assumptions!$B$19+Assumptions!$B$28)/(1-Assumptions!$B$12-Assumptions!$B$13) | D36: =(Assumptions!$B$19+Assumptions!$B$28)/(1-Assumptions!$B$11-Assumptions!$B$13)
A37: Zone 4 — $12 travel | B37: =(Assumptions!$B$20+Assumptions!$B$28)/(1-Assumptions!$B$10-Assumptions!$B$13) | C37: =(Assumptions!$B$20+Assumptions!$B$28)/(1-Assumptions!$B$12-Assumptions!$B$13) | D37: =(Assumptions!$B$20+Assumptions!$B$28)/(1-Assumptions!$B$11-Assumptions!$B$13)
A38: Zone 5 — $15 travel | B38: =(Assumptions!$B$21+Assumptions!$B$28)/(1-Assumptions!$B$10-Assumptions!$B$13) | C38: =(Assumptions!$B$21+Assumptions!$B$28)/(1-Assumptions!$B$12-Assumptions!$B$13) | D38: =(Assumptions!$B$21+Assumptions!$B$28)/(1-Assumptions!$B$11-Assumptions!$B$13)
A40: EFFECTIVE MARGIN BY PRICE TIER · At 45% sub rate, Zone 3 ($10 travel) — update in Assumptions
A41: Formula: 1 − Sub Rate % − (Travel + Fixed Costs) ÷ Job Price Margin improves as job price increases — fixed costs become a smaller % of larger jobs.
A42: Sq Ft → | B42: 750 | C42: 1000 | D42: 1250 | E42: 1500 | F42: 1800 | G42: 2100 | H42: 2400 | I42: 2700 | J42: 3000 | K42: 3300 | L42: 3600 | M42: 4000 | N42: 4400 | O42: 4800 | P42: 5200 | Q42: 5600 | R42: 6000 | S42: 6499 | T42: 6999 | U42: 7499 | V42: 7999 | W42: 8499 | X42: 8999 | Y42: 9499 | Z42: 9999 | AA42: 10000
A43: Deep Clean Margin % | B43: =IFERROR(1-Assumptions!$B$12-(Assumptions!$B$22+Assumptions!$B$28)/B5,"") | C43: =IFERROR(1-Assumptions!$B$12-(Assumptions!$B$22+Assumptions!$B$28)/C5,"") | D43: =IFERROR(1-Assumptions!$B$12-(Assumptions!$B$22+Assumptions!$B$28)/D5,"") | E43: =IFERROR(1-Assumptions!$B$12-(Assumptions!$B$22+Assumptions!$B$28)/E5,"") | F43: =IFERROR(1-Assumptions!$B$12-(Assumptions!$B$22+Assumptions!$B$28)/F5,"") | G43: =IFERROR(1-Assumptions!$B$12-(Assumptions!$B$22+Assumptions!$B$28)/G5,"") | H43: =IFERROR(1-Assumptions!$B$12-(Assumptions!$B$22+Assumptions!$B$28)/H5,"") | I43: =IFERROR(1-Assumptions!$B$12-(Assumptions!$B$22+Assumptions!$B$28)/I5,"") | ... AA43: =IFERROR(1-Assumptions!$B$12-(Assumptions!$B$22+Assumptions!$B$28)/AA5,"")
A44: Standard Clean Margin % | B44: =IFERROR(1-Assumptions!$B$12-(Assumptions!$B$22+Assumptions!$B$28)/B11,"") | C44: =IFERROR(1-Assumptions!$B$12-(Assumptions!$B$22+Assumptions!$B$28)/C11,"") | D44: =IFERROR(1-Assumptions!$B$12-(Assumptions!$B$22+Assumptions!$B$28)/D11,"") | E44: =IFERROR(1-Assumptions!$B$12-(Assumptions!$B$22+Assumptions!$B$28)/E11,"") | F44: =IFERROR(1-Assumptions!$B$12-(Assumptions!$B$22+Assumptions!$B$28)/F11,"") | G44: =IFERROR(1-Assumptions!$B$12-(Assumptions!$B$22+Assumptions!$B$28)/G11,"") | H44: =IFERROR(1-Assumptions!$B$12-(Assumptions!$B$22+Assumptions!$B$28)/H11,"") | I44: =IFERROR(1-Assumptions!$B$12-(Assumptions!$B$22+Assumptions!$B$28)/I11,"") | ... AA44: =IFERROR(1-Assumptions!$B$12-(Assumptions!$B$22+Assumptions!$B$28)/AA11,"")
A45: Weekly Clean Margin % | B45: =IFERROR(1-Assumptions!$B$12-(Assumptions!$B$22+Assumptions!$B$28)/B14,"") | C45: =IFERROR(1-Assumptions!$B$12-(Assumptions!$B$22+Assumptions!$B$28)/C14,"") | D45: =IFERROR(1-Assumptions!$B$12-(Assumptions!$B$22+Assumptions!$B$28)/D14,"") | E45: =IFERROR(1-Assumptions!$B$12-(Assumptions!$B$22+Assumptions!$B$28)/E14,"") | F45: =IFERROR(1-Assumptions!$B$12-(Assumptions!$B$22+Assumptions!$B$28)/F14,"") | G45: =IFERROR(1-Assumptions!$B$12-(Assumptions!$B$22+Assumptions!$B$28)/G14,"") | H45: =IFERROR(1-Assumptions!$B$12-(Assumptions!$B$22+Assumptions!$B$28)/H14,"") | I45: =IFERROR(1-Assumptions!$B$12-(Assumptions!$B$22+Assumptions!$B$28)/I14,"") | ... AA45: =IFERROR(1-Assumptions!$B$12-(Assumptions!$B$22+Assumptions!$B$28)/AA14,"")
...
