Workbook

Sheet Assumptions
A1: THE VALLEY CLEAN TEAM — PRICING ASSUMPTIONS
A3: CLIENT-FACING BILLING RATES
A4: Input | B4: Value | C4: Notes
A5: Standard hourly billing rate | B5: 62.5 | C5: Rate per cleaner-hour quoted to clients
A6: Post-construction hourly rate | B6: 95 | C6: Higher rate for specialty post-construction work
A8: SUBCONTRACTOR MODEL
A9: Input | B9: Value | C9: Notes
A10: Sub rate — low end | B10: 0.4 | C10: Lowest percentage you pay a sub
A11: Sub rate — high end | B11: 0.5 | C11: Highest percentage you pay a sub
A12: Sub rate for margin calculations | B12: 0.45 | C12: Midpoint — adjust to your most common rate
A13: Target gross margin | B13: 0.38 | C13: (Revenue − All Costs) ÷ Revenue
A15: TRAVEL FEES BY ZONE · Flat per-job fee paid to sub for gas
A16: Input | B16: Value | C16: Notes
A17: Zone 1 — Nashville core (closest) | B17: 5 | C17: Local jobs
A18: Zone 2 | B18: 8
A19: Zone 3 — Mid-range | B19: 10
A20: Zone 4 | B20: 12
A21: Zone 5 — Furthest out | B21: 15 | C21: Furthest service area
A22: Zone used for margin calculations | B22: =B19 -> 10 | C22: Defaults to Zone 3 — change formula to B17–B21 for different zone
A24: TODD'S FIXED COSTS PER JOB · Costs NOT covered by the sub
A25: Input | B25: Value | C25: Notes
A26: Software & tech (GHL, scheduling, etc.) | B26: 45 | C26: Monthly cost ÷ avg jobs per month — update this number
A27: Marketing & sales allocation | B27: 25 | C27: Monthly ad/lead spend ÷ avg jobs per month
A28: Total fixed cost per job | B28: =B26+B27 -> 70 | C28: Auto-calculated — do not edit
A30: TIME ESTIMATES · Hours per 1,000 sq ft — used for scheduling
A31: Service | B31: Hrs / 1,000 sq ft | C31: Example
A32: Deep clean / first visit | B32: 2.625 | C32: ~21 hrs for an 8,000 sq ft home
A33: Standard / recurring clean | B33: 1.875 | C33: ~15 hrs for an 8,000 sq ft home
A34: Move in / out | B34: 2.625 | C34: Same scope as deep clean
A35: Post-construction final clean | B35: 3.125 | C35: ~25 hrs for an 8,000 sq ft new build
A37: RECURRING DISCOUNTS · Applied to Standard Clean price
A38: Input | B38: Value | C38: Notes
A39: Monthly | B39: 0.15 | C39: 15% off standard
A40: Bi-weekly | B40: 0.25 | C40: 25% off standard
A41: Weekly | B41: 0.3 | C41: 30% off standard
A43: MINIMUM PRICES
A44: Deep clean minimum | B44: 200
A45: Standard clean minimum | B45: 200
A46: Weekly recurring minimum | B46: 150
A47: Move in/out minimum | B47: 350
...

Sheet Pricing Table
A1: THE VALLEY CLEAN TEAM — PRICING TABLE
A2: Orange (cols B–S, 750–6,500 sq ft) = existing pricing. Blue (cols T–Z, 7,000–10,000 sq ft) = extended, market-rate grounded. Amber rows = estimated labor hours for scheduling. Discounts: Monthly −15% | Bi-Weekly −25% | Weekly −30% off Standard.
A3: DEEP CLEAN (First Cleaning)
A4: Sq Ft → | B4: 750 | C4: 1,000 | D4: 1,250 | E4: 1,500 | F4: 1,800 | G4: 2,100 | H4: 2,400 | I4: 2,700 | J4: 3,000 | K4: 3,300 | L4: 3,600 | M4: 4,000 | N4: 4,400 | O4: 4,700 | P4: 5,200 | Q4: 5,600 | R4: 6,000 | S4: 6,500 | T4: 7,000 | U4: 7,500 | V4: 8,000 | W4: 8,500 | X4: 9,000 | Y4: 9,500 | Z4: 10,000
A5: First Cleaning (Deep Clean) | B5: 276 | C5: 311 | D5: 346 | E5: 381 | F5: 416 | G5: 451 | H5: 506 | I5: 561 | J5: 616 | K5: 671 | L5: 726 | M5: 781 | N5: 836 | O5: 891 | P5: 946 | Q5: 1001 | R5: 1056 | S5: 1170 | T5: 1350 | U5: 1550 | V5: 1750 | W5: 1950 | X5: 2150 | Y5: 2350 | Z5: 2550
A6: Per Sq Ft | B6: =IF(B4>0,B5/B4,"") -> 0.368 | C6: =IF(C4>0,C5/C4,"") -> 0.311 | D6: =IF(D4>0,D5/D4,"") -> 0.2768 | E6: =IF(E4>0,E5/E4,"") -> 0.254 | F6: =IF(F4>0,F5/F4,"") -> 0.23111111 | G6: =IF(G4>0,G5/G4,"") -> 0.2147619 | H6: =IF(H4>0,H5/H4,"") -> 0.21083333 | I6: =IF(I4>0,I5/I4,"") -> 0.20777778 | ... Z6: =IF(Z4>0,Z5/Z4,"") -> 0.255
A7: Est. Labor Hours | B7: =ROUND(B4/1000*Assumptions!$B$32,1) -> 2 | C7: =ROUND(C4/1000*Assumptions!$B$32,1) -> 2.6 | D7: =ROUND(D4/1000*Assumptions!$B$32,1) -> 3.3 | E7: =ROUND(E4/1000*Assumptions!$B$32,1) -> 3.9 | F7: =ROUND(F4/1000*Assumptions!$B$32,1) -> 4.7 | G7: =ROUND(G4/1000*Assumptions!$B$32,1) -> 5.5 | H7: =ROUND(H4/1000*Assumptions!$B$32,1) -> 6.3 | I7: =ROUND(I4/1000*Assumptions!$B$32,1) -> 7.1 | ... Z7: =ROUND(Z4/1000*Assumptions!$B$32,1) -> 26.3
A9: STANDARD / RECURRING CLEAN
A10: Sq Ft → | B10: 750 | C10: 1,000 | D10: 1,250 | E10: 1,500 | F10: 1,800 | G10: 2,100 | H10: 2,400 | I10: 2,700 | J10: 3,000 | K10: 3,300 | L10: 3,600 | M10: 4,000 | N10: 4,400 | O10: 4,700 | P10: 5,200 | Q10: 5,600 | R10: 6,000 | S10: 6,500 | T10: 7,000 | U10: 7,500 | V10: 8,000 | W10: 8,500 | X10: 9,000 | Y10: 9,500 | Z10: 10,000
A11: Standard Clean (one-time) | B11: 2 | C11: 211 | D11: 246 | E11: 281 | F11: 316 | G11: 351 | H11: 381 | I11: 436 | J11: 491 | K11: 546 | L11: 601 | M11: 656 | N11: 711 | O11: 766 | P11: 821 | Q11: 876 | R11: 931 | S11: 1045 | T11: 1200 | U11: 1375 | V11: 1550 | W11: 1725 | X11: 1900 | Y11: 2075 | Z11: 2250
A12: Monthly Clean (15% off) | B12: 149 | C12: 179 | D12: 209 | E12: 239 | F12: 268 | G12: 298 | H12: 324 | I12: 370 | J12: 417 | K12: 464 | L12: 511 | M12: 557 | N12: 604 | O12: 651 | P12: 698 | Q12: 744 | R12: 791 | S12: 888 | T12: 1020 | U12: 1170 | V12: 1320 | W12: 1470 | X12: 1615 | Y12: 1760 | Z12: 1910
A13: Bi-Weekly Clean (25% off) | B13: 132 | C13: 158 | D13: 184 | E13: 211 | F13: 237 | G13: 263 | H13: 286 | I13: 327 | J13: 368 | K13: 409 | L13: 451 | M13: 492 | N13: 533 | O13: 574 | P13: 616 | Q13: 657 | R13: 698 | S13: 784 | T13: 900 | U13: 1030 | V13: 1160 | W13: 1290 | X13: 1425 | Y13: 1560 | Z13: 1690
A14: Weekly Clean (30% off) | B14: 123 | C14: 147 | D14: 172 | E14: 196 | F14: 221 | G14: 245 | H14: 266 | I14: 305 | J14: 343 | K14: 382 | L14: 420 | M14: 459 | N14: 497 | O14: 536 | P14: 574 | Q14: 613 | R14: 651 | S14: 732 | T14: 840 | U14: 960 | V14: 1090 | W14: 1210 | X14: 1330 | Y14: 1450 | Z14: 1580
A15: Weekly — Per Sq Ft | B15: =IF(B10>0,B14/B10,"") -> 0.164 | C15: =IF(C10>0,C14/C10,"") -> 0.147 | D15: =IF(D10>0,D14/D10,"") -> 0.1376 | E15: =IF(E10>0,E14/E10,"") -> 0.13066667 | F15: =IF(F10>0,F14/F10,"") -> 0.12277778 | G15: =IF(G10>0,G14/G10,"") -> 0.11666667 | H15: =IF(H10>0,H14/H10,"") -> 0.11083333 | I15: =IF(I10>0,I14/I10,"") -> 0.11296296 | ... Z15: =IF(Z10>0,Z14/Z10,"") -> 0.158
A16: Est. Labor Hours | B16: =ROUND(B10/1000*Assumptions!$B$33,1) -> 1.4 | C16: =ROUND(C10/1000*Assumptions!$B$33,1) -> 1.9 | D16: =ROUND(D10/1000*Assumptions!$B$33,1) -> 2.3 | E16: =ROUND(E10/1000*Assumptions!$B$33,1) -> 2.8 | F16: =ROUND(F10/1000*Assumptions!$B$33,1) -> 3.4 | G16: =ROUND(G10/1000*Assumptions!$B$33,1) -> 3.9 | H16: =ROUND(H10/1000*Assumptions!$B$33,1) -> 4.5 | I16: =ROUND(I10/1000*Assumptions!$B$33,1) -> 5.1 | ... Z16: =ROUND(Z10/1000*Assumptions!$B$33,1) -> 18.8
A18: MOVE IN / MOVE OUT (+$75 above Deep Clean)
A19: Sq Ft → | B19: 750 | C19: 1,000 | D19: 1,250 | E19: 1,500 | F19: 1,800 | G19: 2,100 | H19: 2,400 | I19: 2,700 | J19: 3,000 | K19: 3,300 | L19: 3,600 | M19: 4,000 | N19: 4,400 | O19: 4,700 | P19: 5,200 | Q19: 5,600 | R19: 6,000 | S19: 6,500 | T19: 7,000 | U19: 7,500 | V19: 8,000 | W19: 8,500 | X19: 9,000 | Y19: 9,500 | Z19: 10,000
A20: Move In / Out Clean | B20: 351 | C20: 386 | D20: 421 | E20: 456 | F20: 491 | G20: 526 | H20: 581 | I20: 636 | J20: 691 | K20: 746 | L20: 801 | M20: 856 | N20: 911 | O20: 966 | P20: 1021 | Q20: 1076 | R20: 1131 | S20: 1181 | T20: 1425 | U20: 1625 | V20: 1825 | W20: 2025 | X20: 2225 | Y20: 2425 | Z20: 2625
A21: Per Sq Ft | B21: =IF(B19>0,B20/B19,"") -> 0.468 | C21: =IF(C19>0,C20/C19,"") -> 0.386 | D21: =IF(D19>0,D20/D19,"") -> 0.3368 | E21: =IF(E19>0,E20/E19,"") -> 0.304 | F21: =IF(F19>0,F20/F19,"") -> 0.27277778 | G21: =IF(G19>0,G20/G19,"") -> 0.25047619 | H21: =IF(H19>0,H20/H19,"") -> 0.24208333 | I21: =IF(I19>0,I20/I19,"") -> 0.23555556 | ... Z21: =IF(Z19>0,Z20/Z19,"") -> 0.2625
A22: Est. Labor Hours | B22: =ROUND(B19/1000*Assumptions!$B$34,1) -> 2 | C22: =ROUND(C19/1000*Assumptions!$B$34,1) -> 2.6 | D22: =ROUND(D19/1000*Assumptions!$B$34,1) -> 3.3 | E22: =ROUND(E19/1000*Assumptions!$B$34,1) -> 3.9 | F22: =ROUND(F19/1000*Assumptions!$B$34,1) -> 4.7 | G22: =ROUND(G19/1000*Assumptions!$B$34,1) -> 5.5 | H22: =ROUND(H19/1000*Assumptions!$B$34,1) -> 6.3 | I22: =ROUND(I19/1000*Assumptions!$B$34,1) -> 7.1 | ... Z22: =ROUND(Z19/1000*Assumptions!$B$34,1) -> 26.3
A24: POST-CONSTRUCTION CLEAN UP
A25: ⚠️ RATE CHANGE FOR 7,000+ SQ FT: Existing prices used '50% above Move In/Out' formula — which underprices large new builds. Extended range uses $0.50/sq ft, grounded in Nashville post-construction market rates ($3,200–$4,400 for 8,000 sq ft).
A26: Sq Ft → | B26: 750 | C26: 1,000 | D26: 1,250 | E26: 1,500 | F26: 1,800 | G26: 2,100 | H26: 2,400 | I26: 2,700 | J26: 3,000 | K26: 3,300 | L26: 3,600 | M26: 4,000 | N26: 4,400 | O26: 4,700 | P26: 5,200 | Q26: 5,600 | R26: 6,000 | S26: 6,500 | T26: 7,000 | U26: 7,500 | V26: 8,000 | W26: 8,500 | X26: 9,000 | Y26: 9,500 | Z26: 10,000
A27: Construction Clean Up | B27: 526 | C27: 579 | D27: 631 | E27: 684 | F27: 736 | G27: 789 | H27: 871 | I27: 954 | J27: 1036 | K27: 1119 | L27: 1201 | M27: 1284 | N27: 1366 | O27: 1449 | P27: 1531 | Q27: 1614 | R27: 1696 | S27: 1820 | T27: 3500 | U27: 3750 | V27: 4000 | W27: 4250 | X27: 4500 | Y27: 4750 | Z27: 5000
A28: Per Sq Ft | B28: =IF(B26>0,B27/B26,"") -> 0.70133333 | C28: =IF(C26>0,C27/C26,"") -> 0.579 | D28: =IF(D26>0,D27/D26,"") -> 0.5048 | E28: =IF(E26>0,E27/E26,"") -> 0.456 | F28: =IF(F26>0,F27/F26,"") -> 0.40888889 | G28: =IF(G26>0,G27/G26,"") -> 0.37571429 | H28: =IF(H26>0,H27/H26,"") -> 0.36291667 | I28: =IF(I26>0,I27/I26,"") -> 0.35333333 | ... Z28: =IF(Z26>0,Z27/Z26,"") -> 0.5
A29: Est. Labor Hours | B29: =ROUND(B26/1000*Assumptions!$B$35,1) -> 2.3 | C29: =ROUND(C26/1000*Assumptions!$B$35,1) -> 3.1 | D29: =ROUND(D26/1000*Assumptions!$B$35,1) -> 3.9 | E29: =ROUND(E26/1000*Assumptions!$B$35,1) -> 4.7 | F29: =ROUND(F26/1000*Assumptions!$B$35,1) -> 5.6 | G29: =ROUND(G26/1000*Assumptions!$B$35,1) -> 6.6 | H29: =ROUND(H26/1000*Assumptions!$B$35,1) -> 7.5 | I29: =ROUND(I26/1000*Assumptions!$B$35,1) -> 8.4 | ... Z29: =ROUND(Z26/1000*Assumptions!$B$35,1) -> 31.3
A31: SUBCONTRACTOR FLOOR CHECK — Minimum Viable Job Price by Zone & Sub Rate
A32: Formula: (Travel Fee + Fixed Costs Per Job) ÷ (1 − Sub Rate % − Target Margin %) Any job priced above the floor for its zone/sub rate hits your margin target.
A33: Zone / Travel Fee | B33: 40% Sub Rate | C33: 45% Sub Rate | D33: 50% Sub Rate
A34: Zone 1 — $5 travel | B34: =(Assumptions!$B$17+Assumptions!$B$28)/(1-Assumptions!$B$10-Assumptions!$B$13) -> 340.90909 | C34: =(Assumptions!$B$17+Assumptions!$B$28)/(1-Assumptions!$B$12-Assumptions!$B$13) -> 441.17647 | D34: =(Assumptions!$B$17+Assumptions!$B$28)/(1-Assumptions!$B$11-Assumptions!$B$13) -> 625 | E34: ← Any job priced above the number in its row hits your margin target. Larger jobs generate higher margins because fixed costs become a smaller % of revenue. See Margin table below.
A35: Zone 2 — $8 travel | B35: =(Assumptions!$B$18+Assumptions!$B$28)/(1-Assumptions!$B$10-Assumptions!$B$13) -> 354.54545 | C35: =(Assumptions!$B$18+Assumptions!$B$28)/(1-Assumptions!$B$12-Assumptions!$B$13) -> 458.82353 | D35: =(Assumptions!$B$18+Assumptions!$B$28)/(1-Assumptions!$B$11-Assumptions!$B$13) -> 650
A36: Zone 3 — $10 travel | B36: =(Assumptions!$B$19+Assumptions!$B$28)/(1-Assumptions!$B$10-Assumptions!$B$13) -> 363.63636 | C36: =(Assumptions!$B$19+Assumptions!$B$28)/(1-Assumptions!$B$12-Assumptions!$B$13) -> 470.58824 | D36: =(Assumptions!$B$19+Assumptions!$B$28)/(1-Assumptions!$B$11-Assumptions!$B$13) -> 666.66667
A37: Zone 4 — $12 travel | B37: =(Assumptions!$B$20+Assumptions!$B$28)/(1-Assumptions!$B$10-Assumptions!$B$13) -> 372.72727 | C37: =(Assumptions!$B$20+Assumptions!$B$28)/(1-Assumptions!$B$12-Assumptions!$B$13) -> 482.35294 | D37: =(Assumptions!$B$20+Assumptions!$B$28)/(1-Assumptions!$B$11-Assumptions!$B$13) -> 683.33333
A38: Zone 5 — $15 travel | B38: =(Assumptions!$B$21+Assumptions!$B$28)/(1-Assumptions!$B$10-Assumptions!$B$13) -> 386.36364 | C38: =(Assumptions!$B$21+Assumptions!$B$28)/(1-Assumptions!$B$12-Assumptions!$B$13) -> 500 | D38: =(Assumptions!$B$21+Assumptions!$B$28)/(1-Assumptions!$B$11-Assumptions!$B$13) -> 708.33333
A40: EFFECTIVE MARGIN BY PRICE TIER · At 45% sub rate, Zone 3 ($10 travel) — update in Assumptions
A41: Formula: 1 − Sub Rate % − (Travel + Fixed Costs) ÷ Job Price Margin improves as job price increases — fixed costs become a smaller % of larger jobs.
A42: Sq Ft → | B42: 750 | C42: 1,000 | D42: 1,250 | E42: 1,500 | F42: 1,800 | G42: 2,100 | H42: 2,400 | I42: 2,700 | J42: 3,000 | K42: 3,300 | L42: 3,600 | M42: 4,000 | N42: 4,400 | O42: 4,700 | P42: 5,200 | Q42: 5,600 | R42: 6,000 | S42: 6,500 | T42: 7,000 | U42: 7,500 | V42: 8,000 | W42: 8,500 | X42: 9,000 | Y42: 9,500 | Z42: 10,000
A43: Deep Clean Margin % | B43: =IFERROR(1-Assumptions!$B$12-(Assumptions!$B$22+Assumptions!$B$28)/B5,"") -> 0.26014493 | C43: =IFERROR(1-Assumptions!$B$12-(Assumptions!$B$22+Assumptions!$B$28)/C5,"") -> 0.29276527 | D43: =IFERROR(1-Assumptions!$B$12-(Assumptions!$B$22+Assumptions!$B$28)/D5,"") -> 0.31878613 | E43: =IFERROR(1-Assumptions!$B$12-(Assumptions!$B$22+Assumptions!$B$28)/E5,"") -> 0.34002625 | F43: =IFERROR(1-Assumptions!$B$12-(Assumptions!$B$22+Assumptions!$B$28)/F5,"") -> 0.35769231 | G43: =IFERROR(1-Assumptions!$B$12-(Assumptions!$B$22+Assumptions!$B$28)/G5,"") -> 0.37261641 | H43: =IFERROR(1-Assumptions!$B$12-(Assumptions!$B$22+Assumptions!$B$28)/H5,"") -> 0.39189723 | I43: =IFERROR(1-Assumptions!$B$12-(Assumptions!$B$22+Assumptions!$B$28)/I5,"") -> 0.4073975 | ... Z43: =IFERROR(1-Assumptions!$B$12-(Assumptions!$B$22+Assumptions!$B$28)/Z5,"") -> 0.51862745
A44: Standard Clean Margin % | B44: =IFERROR(1-Assumptions!$B$12-(Assumptions!$B$22+Assumptions!$B$28)/B11,"") -> -39.45 | C44: =IFERROR(1-Assumptions!$B$12-(Assumptions!$B$22+Assumptions!$B$28)/C11,"") -> 0.17085308 | D44: =IFERROR(1-Assumptions!$B$12-(Assumptions!$B$22+Assumptions!$B$28)/D11,"") -> 0.22479675 | E44: =IFERROR(1-Assumptions!$B$12-(Assumptions!$B$22+Assumptions!$B$28)/E11,"") -> 0.26530249 | F44: =IFERROR(1-Assumptions!$B$12-(Assumptions!$B$22+Assumptions!$B$28)/F11,"") -> 0.29683544 | G44: =IFERROR(1-Assumptions!$B$12-(Assumptions!$B$22+Assumptions!$B$28)/G11,"") -> 0.32207977 | H44: =IFERROR(1-Assumptions!$B$12-(Assumptions!$B$22+Assumptions!$B$28)/H11,"") -> 0.34002625 | I44: =IFERROR(1-Assumptions!$B$12-(Assumptions!$B$22+Assumptions!$B$28)/I11,"") -> 0.36651376 | ... Z44: =IFERROR(1-Assumptions!$B$12-(Assumptions!$B$22+Assumptions!$B$28)/Z11,"") -> 0.51444444
A45: Weekly Clean Margin % | B45: =IFERROR(1-Assumptions!$B$12-(Assumptions!$B$22+Assumptions!$B$28)/B14,"") -> -0.1004065 | C45: =IFERROR(1-Assumptions!$B$12-(Assumptions!$B$22+Assumptions!$B$28)/C14,"") -> 0.0057823129 | D45: =IFERROR(1-Assumptions!$B$12-(Assumptions!$B$22+Assumptions!$B$28)/D14,"") -> 0.084883721 | E45: =IFERROR(1-Assumptions!$B$12-(Assumptions!$B$22+Assumptions!$B$28)/E14,"") -> 0.14183673 | F45: =IFERROR(1-Assumptions!$B$12-(Assumptions!$B$22+Assumptions!$B$28)/F14,"") -> 0.18800905 | G45: =IFERROR(1-Assumptions!$B$12-(Assumptions!$B$22+Assumptions!$B$28)/G14,"") -> 0.22346939 | H45: =IFERROR(1-Assumptions!$B$12-(Assumptions!$B$22+Assumptions!$B$28)/H14,"") -> 0.24924812 | I45: =IFERROR(1-Assumptions!$B$12-(Assumptions!$B$22+Assumptions!$B$28)/I14,"") -> 0.28770492 | ... Z45: =IFERROR(1-Assumptions!$B$12-(Assumptions!$B$22+Assumptions!$B$28)/Z14,"") -> 0.49936709
...
